    return self[key]
           ~~~~^^^^^
  File "/Users/peter/miniforge3/envs/env-streamlit-addaxai/lib/python3.11/site-packages/streamlit/runtime/state/session_state_proxy.py", line 101, in __getitem__
    return get_session_state()[key]
           ~~~~~~~~~~~~~~~~~~~^^^^^
  File "/Users/peter/miniforge3/envs/env-streamlit-addaxai/lib/python3.11/site-packages/streamlit/runtime/state/safe_session_state.py", line 96, in __getitem__
    return self._state[key]
           ~~~~~~~~~~~^^^^^
  File "/Users/peter/miniforge3/envs/env-streamlit-addaxai/lib/python3.11/site-packages/streamlit/runtime/state/session_state.py", line 456, in __getitem__
    raise KeyError(_missing_key_error_message(key))
KeyError: 'st.session_state has no key "coords_found_in_exif". Did you forget to initialize it? More info: https://docs.streamlit.io/develop/concepts/architecture/session-state#initialization'

During handling of the above exception, another exception occurred:

Traceback (most recent call last):
  File "/Users/peter/miniforge3/envs/env-streamlit-addaxai/lib/python3.11/site-packages/streamlit/runtime/scriptrunner/exec_code.py", line 121, in exec_func_with_error_handling
    result = func()
             ^^^^^^
  File "/Users/peter/miniforge3/envs/env-streamlit-addaxai/lib/python3.11/site-packages/streamlit/runtime/scriptrunner/script_runner.py", line 645, in code_to_exec
    exec(code, module.__dict__)
  File "/Applications/AddaxAI_files/AddaxAI/streamlit-AddaxAI/frontend/main.py", line 250, in <module>
    pg.run()
  File "/Users/peter/miniforge3/envs/env-streamlit-addaxai/lib/python3.11/site-packages/streamlit/navigation/page.py", line 297, in run
    exec(code, module.__dict__)
  File "/Applications/AddaxAI_files/AddaxAI/streamlit-AddaxAI/frontend/analyse_advanced.py", line 138, in <module>
    selected_locationID = location_selector_widget()
                          ^^^^^^^^^^^^^^^^^^^^^^^^^^
  File "/Applications/AddaxAI_files/AddaxAI/streamlit-AddaxAI/backend/utils.py", line 109, in location_selector_widget
    if st.session_state.coords_found_in_exif:
       ^^^^^^^^^^^^^^^^^^^^^^^^^^^^^^^^^^^^^
  File "/Users/peter/miniforge3/envs/env-streamlit-addaxai/lib/python3.11/site-packages/streamlit/runtime/state/session_state_proxy.py", line 132, in __getattr__
    raise AttributeError(_missing_attr_error_message(key))
AttributeError: st.session_state has no attribute "coords_found_in_exif". Did you forget to initialize it? More info: https://docs.streamlit.io/develop/concepts/architecture/session-state#initialization
2025-06-28 11:43:10.648 Uncaught app execution
Traceback (most recent call last):
  File "/Users/peter/miniforge3/envs/env-streamlit-addaxai/lib/python3.11/site-packages/streamlit/runtime/scriptrunner/exec_code.py", line 121, in exec_func_with_error_handling
    result = func()
             ^^^^^^
  File "/Users/peter/miniforge3/envs/env-streamlit-addaxai/lib/python3.11/site-packages/streamlit/runtime/scriptrunner/script_runner.py", line 645, in code_to_exec
    exec(code, module.__dict__)
  File "/Applications/AddaxAI_files/AddaxAI/streamlit-AddaxAI/frontend/main.py", line 250, in <module>
    pg.run()
  File "/Users/peter/miniforge3/envs/env-streamlit-addaxai/lib/python3.11/site-packages/streamlit/navigation/page.py", line 297, in run
    exec(code, module.__dict__)
  File "/Applications/AddaxAI_files/AddaxAI/streamlit-AddaxAI/frontend/analyse_advanced.py", line 82, in <module>
    check_folder_metadata()
  File "/Applications/AddaxAI_files/AddaxAI/streamlit-AddaxAI/backend/utils.py", line 1212, in check_folder_metadata
    update_vars(section="analyse_advanced",
  File "/Applications/AddaxAI_files/AddaxAI/streamlit-AddaxAI/backend/utils.py", line 421, in update_vars
    json.dump(settings, file, indent=2)
  File "/Users/peter/miniforge3/envs/env-streamlit-addaxai/lib/python3.11/json/__init__.py", line 179, in dump
    for chunk in iterable:
  File "/Users/peter/miniforge3/envs/env-streamlit-addaxai/lib/python3.11/json/encoder.py", line 432, in _iterencode
    yield from _iterencode_dict(o, _current_indent_level)
  File "/Users/peter/miniforge3/envs/env-streamlit-addaxai/lib/python3.11/json/encoder.py", line 406, in _iterencode_dict
    yield from chunks
  File "/Users/peter/miniforge3/envs/env-streamlit-addaxai/lib/python3.11/json/encoder.py", line 406, in _iterencode_dict
    yield from chunks
  File "/Users/peter/miniforge3/envs/env-streamlit-addaxai/lib/python3.11/json/encoder.py", line 406, in _iterencode_dict
    yield from chunks
  File "/Users/peter/miniforge3/envs/env-streamlit-addaxai/lib/python3.11/json/encoder.py", line 439, in _iterencode
    o = _default(o)
        ^^^^^^^^^^^
  File "/Users/peter/miniforge3/envs/env-streamlit-addaxai/lib/python3.11/json/encoder.py", line 180, in default
    raise TypeError(f'Object of type {o.__class__.__name__} '
TypeError: Object of type datetime is not JSON serializable
2025-06-28 11:47:28.050 Uncaught app execution
Traceback (most recent call last):
  File "/Users/peter/miniforge3/envs/env-streamlit-addaxai/lib/python3.11/site-packages/streamlit/runtime/scriptrunner/exec_code.py", line 121, in exec_func_with_error_handling
    result = func()
             ^^^^^^
  File "/Users/peter/miniforge3/envs/env-streamlit-addaxai/lib/python3.11/site-packages/streamlit/runtime/scriptrunner/script_runner.py", line 645, in code_to_exec
    exec(code, module.__dict__)
  File "/Applications/AddaxAI_files/AddaxAI/streamlit-AddaxAI/frontend/main.py", line 190, in <module>
    lang = settings["vars"]["global"]["lang"]
           ~~~~~~~~^^^^^^^^
KeyError: 'vars'
2025-06-28 11:47:48.508 Uncaught app execution
Traceback (most recent call last):
  File "/Users/peter/miniforge3/envs/env-streamlit-addaxai/lib/python3.11/site-packages/streamlit/runtime/scriptrunner/exec_code.py", line 121, in exec_func_with_error_handling
    result = func()
             ^^^^^^
  File "/Users/peter/miniforge3/envs/env-streamlit-addaxai/lib/python3.11/site-packages/streamlit/runtime/scriptrunner/script_runner.py", line 645, in code_to_exec
    exec(code, module.__dict__)
  File "/Applications/AddaxAI_files/AddaxAI/streamlit-AddaxAI/frontend/main.py", line 250, in <module>
    pg.run()
  File "/Users/peter/miniforge3/envs/env-streamlit-addaxai/lib/python3.11/site-packages/streamlit/navigation/page.py", line 297, in run
    exec(code, module.__dict__)
  File "/Applications/AddaxAI_files/AddaxAI/streamlit-AddaxAI/frontend/analyse_advanced.py", line 82, in <module>
    check_folder_metadata()
  File "/Applications/AddaxAI_files/AddaxAI/streamlit-AddaxAI/backend/utils.py", line 1218, in check_folder_metadata
    update_vars(section="analyse_advanced",
  File "/Applications/AddaxAI_files/AddaxAI/streamlit-AddaxAI/backend/utils.py", line 427, in update_vars
    json.dump(settings, file, indent=2)
  File "/Users/peter/miniforge3/envs/env-streamlit-addaxai/lib/python3.11/json/__init__.py", line 179, in dump
    for chunk in iterable:
  File "/Users/peter/miniforge3/envs/env-streamlit-addaxai/lib/python3.11/json/encoder.py", line 432, in _iterencode
    yield from _iterencode_dict(o, _current_indent_level)
  File "/Users/peter/miniforge3/envs/env-streamlit-addaxai/lib/python3.11/json/encoder.py", line 406, in _iterencode_dict
    yield from chunks
  File "/Users/peter/miniforge3/envs/env-streamlit-addaxai/lib/python3.11/json/encoder.py", line 406, in _iterencode_dict
    yield from chunks
  File "/Users/peter/miniforge3/envs/env-streamlit-addaxai/lib/python3.11/json/encoder.py", line 406, in _iterencode_dict
    yield from chunks
  File "/Users/peter/miniforge3/envs/env-streamlit-addaxai/lib/python3.11/json/encoder.py", line 439, in _iterencode
    o = _default(o)
        ^^^^^^^^^^^
  File "/Users/peter/miniforge3/envs/env-streamlit-addaxai/lib/python3.11/json/encoder.py", line 180, in default
    raise TypeError(f'Object of type {o.__class__.__name__} '
TypeError: Object of type datetime is not JSON serializable
2025-06-28 11:50:02.590 Uncaught app execution
Traceback (most recent call last):
  File "/Users/peter/miniforge3/envs/env-streamlit-addaxai/lib/python3.11/site-packages/streamlit/runtime/state/session_state.py", line 454, in __getitem__
    return self._getitem(widget_id, key)
           ^^^^^^^^^^^^^^^^^^^^^^^^^^^^^
  File "/Users/peter/miniforge3/envs/env-streamlit-addaxai/lib/python3.11/site-packages/streamlit/runtime/state/session_state.py", line 499, in _getitem
    raise KeyError
KeyError

During handling of the above exception, another exception occurred:

Traceback (most recent call last):
  File "/Users/peter/miniforge3/envs/env-streamlit-addaxai/lib/python3.11/site-packages/streamlit/runtime/state/session_state_proxy.py", line 130, in __getattr__
    return self[key]
           ~~~~^^^^^
  File "/Users/peter/miniforge3/envs/env-streamlit-addaxai/lib/python3.11/site-packages/streamlit/runtime/state/session_state_proxy.py", line 101, in __getitem__
    return get_session_state()[key]
           ~~~~~~~~~~~~~~~~~~~^^^^^
  File "/Users/peter/miniforge3/envs/env-streamlit-addaxai/lib/python3.11/site-packages/streamlit/runtime/state/safe_session_state.py", line 96, in __getitem__
    return self._state[key]
           ~~~~~~~~~~~^^^^^
  File "/Users/peter/miniforge3/envs/env-streamlit-addaxai/lib/python3.11/site-packages/streamlit/runtime/state/session_state.py", line 456, in __getitem__
    raise KeyError(_missing_key_error_message(key))
KeyError: 'st.session_state has no key "coords_found_in_exif". Did you forget to initialize it? More info: https://docs.streamlit.io/develop/concepts/architecture/session-state#initialization'

During handling of the above exception, another exception occurred:

Traceback (most recent call last):
  File "/Users/peter/miniforge3/envs/env-streamlit-addaxai/lib/python3.11/site-packages/streamlit/runtime/scriptrunner/exec_code.py", line 121, in exec_func_with_error_handling
    result = func()
             ^^^^^^
  File "/Users/peter/miniforge3/envs/env-streamlit-addaxai/lib/python3.11/site-packages/streamlit/runtime/scriptrunner/script_runner.py", line 645, in code_to_exec
    exec(code, module.__dict__)
  File "/Applications/AddaxAI_files/AddaxAI/streamlit-AddaxAI/frontend/main.py", line 250, in <module>
    pg.run()
  File "/Users/peter/miniforge3/envs/env-streamlit-addaxai/lib/python3.11/site-packages/streamlit/navigation/page.py", line 297, in run
    exec(code, module.__dict__)
  File "/Applications/AddaxAI_files/AddaxAI/streamlit-AddaxAI/frontend/analyse_advanced.py", line 138, in <module>
    selected_locationID = location_selector_widget()
                          ^^^^^^^^^^^^^^^^^^^^^^^^^^
  File "/Applications/AddaxAI_files/AddaxAI/streamlit-AddaxAI/backend/utils.py", line 109, in location_selector_widget
    if st.session_state.coords_found_in_exif:
       ^^^^^^^^^^^^^^^^^^^^^^^^^^^^^^^^^^^^^
  File "/Users/peter/miniforge3/envs/env-streamlit-addaxai/lib/python3.11/site-packages/streamlit/runtime/state/session_state_proxy.py", line 132, in __getattr__
    raise AttributeError(_missing_attr_error_message(key))
AttributeError: st.session_state has no attribute "coords_found_in_exif". Did you forget to initialize it? More info: https://docs.streamlit.io/develop/concepts/architecture/session-state#initialization
2025-06-28 11:50:12.669 Uncaught app execution
Traceback (most recent call last):
  File "/Users/peter/miniforge3/envs/env-streamlit-addaxai/lib/python3.11/site-packages/streamlit/runtime/state/session_state.py", line 454, in __getitem__
    return self._getitem(widget_id, key)
           ^^^^^^^^^^^^^^^^^^^^^^^^^^^^^
  File "/Users/peter/miniforge3/envs/env-streamlit-addaxai/lib/python3.11/site-packages/streamlit/runtime/state/session_state.py", line 499, in _getitem
    raise KeyError
KeyError

During handling of the above exception, another exception occurred:

Traceback (most recent call last):
  File "/Users/peter/miniforge3/envs/env-streamlit-addaxai/lib/python3.11/site-packages/streamlit/runtime/state/session_state_proxy.py", line 130, in __getattr__
    return self[key]
           ~~~~^^^^^
  File "/Users/peter/miniforge3/envs/env-streamlit-addaxai/lib/python3.11/site-packages/streamlit/runtime/state/session_state_proxy.py", line 101, in __getitem__
    return get_session_state()[key]
           ~~~~~~~~~~~~~~~~~~~^^^^^
  File "/Users/peter/miniforge3/envs/env-streamlit-addaxai/lib/python3.11/site-packages/streamlit/runtime/state/safe_session_state.py", line 96, in __getitem__
    return self._state[key]
           ~~~~~~~~~~~^^^^^
  File "/Users/peter/miniforge3/envs/env-streamlit-addaxai/lib/python3.11/site-packages/streamlit/runtime/state/session_state.py", line 456, in __getitem__
    raise KeyError(_missing_key_error_message(key))
KeyError: 'st.session_state has no key "coords_found_in_exif". Did you forget to initialize it? More info: https://docs.streamlit.io/develop/concepts/architecture/session-state#initialization'

During handling of the above exception, another exception occurred:

Traceback (most recent call last):
  File "/Users/peter/miniforge3/envs/env-streamlit-addaxai/lib/python3.11/site-packages/streamlit/runtime/scriptrunner/exec_code.py", line 121, in exec_func_with_error_handling
    result = func()
             ^^^^^^
  File "/Users/peter/miniforge3/envs/env-streamlit-addaxai/lib/python3.11/site-packages/streamlit/runtime/scriptrunner/script_runner.py", line 645, in code_to_exec
    exec(code, module.__dict__)
  File "/Applications/AddaxAI_files/AddaxAI/streamlit-AddaxAI/frontend/main.py", line 250, in <module>
    pg.run()
  File "/Users/peter/miniforge3/envs/env-streamlit-addaxai/lib/python3.11/site-packages/streamlit/navigation/page.py", line 297, in run
    exec(code, module.__dict__)
  File "/Applications/AddaxAI_files/AddaxAI/streamlit-AddaxAI/frontend/analyse_advanced.py", line 138, in <module>
    selected_locationID = location_selector_widget()
                          ^^^^^^^^^^^^^^^^^^^^^^^^^^
  File "/Applications/AddaxAI_files/AddaxAI/streamlit-AddaxAI/backend/utils.py", line 109, in location_selector_widget
    if st.session_state.coords_found_in_exif:
       ^^^^^^^^^^^^^^^^^^^^^^^^^^^^^^^^^^^^^
  File "/Users/peter/miniforge3/envs/env-streamlit-addaxai/lib/python3.11/site-packages/streamlit/runtime/state/session_state_proxy.py", line 132, in __getattr__
    raise AttributeError(_missing_attr_error_message(key))
AttributeError: st.session_state has no attribute "coords_found_in_exif". Did you forget to initialize it? More info: https://docs.streamlit.io/develop/concepts/architecture/session-state#initialization
2025-06-28 11:50:12.783 Uncaught app execution
Traceback (most recent call last):
  File "/Users/peter/miniforge3/envs/env-streamlit-addaxai/lib/python3.11/site-packages/streamlit/runtime/state/session_state.py", line 454, in __getitem__
    return self._getitem(widget_id, key)
           ^^^^^^^^^^^^^^^^^^^^^^^^^^^^^
  File "/Users/peter/miniforge3/envs/env-streamlit-addaxai/lib/python3.11/site-packages/streamlit/runtime/state/session_state.py", line 499, in _getitem
    raise KeyError
KeyError

During handling of the above exception, another exception occurred:

Traceback (most recent call last):
  File "/Users/peter/miniforge3/envs/env-streamlit-addaxai/lib/python3.11/site-packages/streamlit/runtime/state/session_state_proxy.py", line 130, in __getattr__
    return self[key]
           ~~~~^^^^^
  File "/Users/peter/miniforge3/envs/env-streamlit-addaxai/lib/python3.11/site-packages/streamlit/runtime/state/session_state_proxy.py", line 101, in __getitem__
    return get_session_state()[key]
           ~~~~~~~~~~~~~~~~~~~^^^^^
  File "/Users/peter/miniforge3/envs/env-streamlit-addaxai/lib/python3.11/site-packages/streamlit/runtime/state/safe_session_state.py", line 96, in __getitem__
    return self._state[key]
           ~~~~~~~~~~~^^^^^
  File "/Users/peter/miniforge3/envs/env-streamlit-addaxai/lib/python3.11/site-packages/streamlit/runtime/state/session_state.py", line 456, in __getitem__
    raise KeyError(_missing_key_error_message(key))
KeyError: 'st.session_state has no key "coords_found_in_exif". Did you forget to initialize it? More info: https://docs.streamlit.io/develop/concepts/architecture/session-state#initialization'

During handling of the above exception, another exception occurred:

Traceback (most recent call last):
  File "/Users/peter/miniforge3/envs/env-streamlit-addaxai/lib/python3.11/site-packages/streamlit/runtime/scriptrunner/exec_code.py", line 121, in exec_func_with_error_handling
    result = func()
             ^^^^^^
  File "/Users/peter/miniforge3/envs/env-streamlit-addaxai/lib/python3.11/site-packages/streamlit/runtime/scriptrunner/script_runner.py", line 645, in code_to_exec
    exec(code, module.__dict__)
  File "/Applications/AddaxAI_files/AddaxAI/streamlit-AddaxAI/frontend/main.py", line 250, in <module>
    pg.run()
  File "/Users/peter/miniforge3/envs/env-streamlit-addaxai/lib/python3.11/site-packages/streamlit/navigation/page.py", line 297, in run
    exec(code, module.__dict__)
  File "/Applications/AddaxAI_files/AddaxAI/streamlit-AddaxAI/frontend/analyse_advanced.py", line 138, in <module>
    selected_locationID = location_selector_widget()
                          ^^^^^^^^^^^^^^^^^^^^^^^^^^
  File "/Applications/AddaxAI_files/AddaxAI/streamlit-AddaxAI/backend/utils.py", line 109, in location_selector_widget
    if st.session_state.coords_found_in_exif:
       ^^^^^^^^^^^^^^^^^^^^^^^^^^^^^^^^^^^^^
  File "/Users/peter/miniforge3/envs/env-streamlit-addaxai/lib/python3.11/site-packages/streamlit/runtime/state/session_state_proxy.py", line 132, in __getattr__
    raise AttributeError(_missing_attr_error_message(key))
AttributeError: st.session_state has no attribute "coords_found_in_exif". Did you forget to initialize it? More info: https://docs.streamlit.io/develop/concepts/architecture/session-state#initialization
2025-06-28 11:50:15.717 Uncaught app execution
Traceback (most recent call last):
  File "/Users/peter/miniforge3/envs/env-streamlit-addaxai/lib/python3.11/site-packages/streamlit/runtime/state/session_state.py", line 454, in __getitem__
    return self._getitem(widget_id, key)
           ^^^^^^^^^^^^^^^^^^^^^^^^^^^^^
  File "/Users/peter/miniforge3/envs/env-streamlit-addaxai/lib/python3.11/site-packages/streamlit/runtime/state/session_state.py", line 499, in _getitem
    raise KeyError
KeyError

During handling of the above exception, another exception occurred:

Traceback (most recent call last):
  File "/Users/peter/miniforge3/envs/env-streamlit-addaxai/lib/python3.11/site-packages/streamlit/runtime/state/session_state_proxy.py", line 130, in __getattr__
    return self[key]
           ~~~~^^^^^
  File "/Users/peter/miniforge3/envs/env-streamlit-addaxai/lib/python3.11/site-packages/streamlit/runtime/state/session_state_proxy.py", line 101, in __getitem__
    return get_session_state()[key]
           ~~~~~~~~~~~~~~~~~~~^^^^^
  File "/Users/peter/miniforge3/envs/env-streamlit-addaxai/lib/python3.11/site-packages/streamlit/runtime/state/safe_session_state.py", line 96, in __getitem__
    return self._state[key]
           ~~~~~~~~~~~^^^^^
  File "/Users/peter/miniforge3/envs/env-streamlit-addaxai/lib/python3.11/site-packages/streamlit/runtime/state/session_state.py", line 456, in __getitem__
    raise KeyError(_missing_key_error_message(key))
KeyError: 'st.session_state has no key "coords_found_in_exif". Did you forget to initialize it? More info: https://docs.streamlit.io/develop/concepts/architecture/session-state#initialization'

During handling of the above exception, another exception occurred:

Traceback (most recent call last):
  File "/Users/peter/miniforge3/envs/env-streamlit-addaxai/lib/python3.11/site-packages/streamlit/runtime/scriptrunner/exec_code.py", line 121, in exec_func_with_error_handling
    result = func()
             ^^^^^^
  File "/Users/peter/miniforge3/envs/env-streamlit-addaxai/lib/python3.11/site-packages/streamlit/runtime/scriptrunner/script_runner.py", line 645, in code_to_exec
    exec(code, module.__dict__)
  File "/Applications/AddaxAI_files/AddaxAI/streamlit-AddaxAI/frontend/main.py", line 250, in <module>
    pg.run()
  File "/Users/peter/miniforge3/envs/env-streamlit-addaxai/lib/python3.11/site-packages/streamlit/navigation/page.py", line 297, in run
    exec(code, module.__dict__)
  File "/Applications/AddaxAI_files/AddaxAI/streamlit-AddaxAI/frontend/analyse_advanced.py", line 138, in <module>
    selected_locationID = location_selector_widget()
                          ^^^^^^^^^^^^^^^^^^^^^^^^^^
  File "/Applications/AddaxAI_files/AddaxAI/streamlit-AddaxAI/backend/utils.py", line 109, in location_selector_widget
    if st.session_state.coords_found_in_exif:
       ^^^^^^^^^^^^^^^^^^^^^^^^^^^^^^^^^^^^^
  File "/Users/peter/miniforge3/envs/env-streamlit-addaxai/lib/python3.11/site-packages/streamlit/runtime/state/session_state_proxy.py", line 132, in __getattr__
    raise AttributeError(_missing_attr_error_message(key))
AttributeError: st.session_state has no attribute "coords_found_in_exif". Did you forget to initialize it? More info: https://docs.streamlit.io/develop/concepts/architecture/session-state#initialization
2025-06-28 11:50:20.557 Uncaught app execution
Traceback (most recent call last):
  File "/Users/peter/miniforge3/envs/env-streamlit-addaxai/lib/python3.11/site-packages/streamlit/runtime/state/session_state.py", line 454, in __getitem__
    return self._getitem(widget_id, key)
           ^^^^^^^^^^^^^^^^^^^^^^^^^^^^^
  File "/Users/peter/miniforge3/envs/env-streamlit-addaxai/lib/python3.11/site-packages/streamlit/runtime/state/session_state.py", line 499, in _getitem
    raise KeyError
KeyError

During handling of the above exception, another exception occurred:

Traceback (most recent call last):
  File "/Users/peter/miniforge3/envs/env-streamlit-addaxai/lib/python3.11/site-packages/streamlit/runtime/state/session_state_proxy.py", line 130, in __getattr__
    return self[key]
           ~~~~^^^^^
  File "/Users/peter/miniforge3/envs/env-streamlit-addaxai/lib/python3.11/site-packages/streamlit/runtime/state/session_state_proxy.py", line 101, in __getitem__
    return get_session_state()[key]
           ~~~~~~~~~~~~~~~~~~~^^^^^
  File "/Users/peter/miniforge3/envs/env-streamlit-addaxai/lib/python3.11/site-packages/streamlit/runtime/state/safe_session_state.py", line 96, in __getitem__
    return self._state[key]
           ~~~~~~~~~~~^^^^^
  File "/Users/peter/miniforge3/envs/env-streamlit-addaxai/lib/python3.11/site-packages/streamlit/runtime/state/session_state.py", line 456, in __getitem__
    raise KeyError(_missing_key_error_message(key))
KeyError: 'st.session_state has no key "coords_found_in_exif". Did you forget to initialize it? More info: https://docs.streamlit.io/develop/concepts/architecture/session-state#initialization'

During handling of the above exception, another exception occurred:

Traceback (most recent call last):
  File "/Users/peter/miniforge3/envs/env-streamlit-addaxai/lib/python3.11/site-packages/streamlit/runtime/scriptrunner/exec_code.py", line 121, in exec_func_with_error_handling
    result = func()
             ^^^^^^
  File "/Users/peter/miniforge3/envs/env-streamlit-addaxai/lib/python3.11/site-packages/streamlit/runtime/scriptrunner/script_runner.py", line 645, in code_to_exec
    exec(code, module.__dict__)
  File "/Applications/AddaxAI_files/AddaxAI/streamlit-AddaxAI/frontend/main.py", line 250, in <module>
    pg.run()
  File "/Users/peter/miniforge3/envs/env-streamlit-addaxai/lib/python3.11/site-packages/streamlit/navigation/page.py", line 297, in run
    exec(code, module.__dict__)
  File "/Applications/AddaxAI_files/AddaxAI/streamlit-AddaxAI/frontend/analyse_advanced.py", line 138, in <module>
    selected_locationID = location_selector_widget()
                          ^^^^^^^^^^^^^^^^^^^^^^^^^^
  File "/Applications/AddaxAI_files/AddaxAI/streamlit-AddaxAI/backend/utils.py", line 109, in location_selector_widget
    if st.session_state.coords_found_in_exif:
       ^^^^^^^^^^^^^^^^^^^^^^^^^^^^^^^^^^^^^
  File "/Users/peter/miniforge3/envs/env-streamlit-addaxai/lib/python3.11/site-packages/streamlit/runtime/state/session_state_proxy.py", line 132, in __getattr__
    raise AttributeError(_missing_attr_error_message(key))
AttributeError: st.session_state has no attribute "coords_found_in_exif". Did you forget to initialize it? More info: https://docs.streamlit.io/develop/concepts/architecture/session-state#initialization
2025-06-28 11:52:10.626 Uncaught app execution
Traceback (most recent call last):
  File "/Users/peter/miniforge3/envs/env-streamlit-addaxai/lib/python3.11/site-packages/streamlit/runtime/scriptrunner/exec_code.py", line 121, in exec_func_with_error_handling
    result = func()
             ^^^^^^
  File "/Users/peter/miniforge3/envs/env-streamlit-addaxai/lib/python3.11/site-packages/streamlit/runtime/scriptrunner/script_runner.py", line 645, in code_to_exec
    exec(code, module.__dict__)
  File "/Applications/AddaxAI_files/AddaxAI/streamlit-AddaxAI/frontend/main.py", line 250, in <module>
    pg.run()
  File "/Users/peter/miniforge3/envs/env-streamlit-addaxai/lib/python3.11/site-packages/streamlit/navigation/page.py", line 297, in run
    exec(code, module.__dict__)
  File "/Applications/AddaxAI_files/AddaxAI/streamlit-AddaxAI/frontend/analyse_advanced.py", line 138, in <module>
    selected_locationID = location_selector_widget()
                          ^^^^^^^^^^^^^^^^^^^^^^^^^^
  File "/Applications/AddaxAI_files/AddaxAI/streamlit-AddaxAI/backend/utils.py", line 122, in location_selector_widget
    info_box(f"Coordinates ({exif_lat:.5f}, {exif_lng:.5f}) were automatically extracted from the image metadata. They will be pre-filled when adding the new location.")
             ^^^^^^^^^^^^^^^^^^^^^^^^^^^^^^^^^^^^^^^^^^^^^^^^^^^^^^^^^^^^^^^^^^^^^^^^^^^^^^^^^^^^^^^^^^^^^^^^^^^^^^^^^^^^^^^^^^^^^^^^^^^^^^^^^^^^^^^^^^^^^^^^^^^^^^^^^^^
ValueError: Unknown format code 'f' for object of type 'str'
2025-06-28 11:52:10.813 Uncaught app execution
Traceback (most recent call last):
  File "/Users/peter/miniforge3/envs/env-streamlit-addaxai/lib/python3.11/site-packages/streamlit/runtime/scriptrunner/exec_code.py", line 121, in exec_func_with_error_handling
    result = func()
             ^^^^^^
  File "/Users/peter/miniforge3/envs/env-streamlit-addaxai/lib/python3.11/site-packages/streamlit/runtime/scriptrunner/script_runner.py", line 645, in code_to_exec
    exec(code, module.__dict__)
  File "/Applications/AddaxAI_files/AddaxAI/streamlit-AddaxAI/frontend/main.py", line 250, in <module>
    pg.run()
  File "/Users/peter/miniforge3/envs/env-streamlit-addaxai/lib/python3.11/site-packages/streamlit/navigation/page.py", line 297, in run
    exec(code, module.__dict__)
  File "/Applications/AddaxAI_files/AddaxAI/streamlit-AddaxAI/frontend/analyse_advanced.py", line 138, in <module>
    selected_locationID = location_selector_widget()
                          ^^^^^^^^^^^^^^^^^^^^^^^^^^
  File "/Applications/AddaxAI_files/AddaxAI/streamlit-AddaxAI/backend/utils.py", line 122, in location_selector_widget
    info_box(f"Coordinates ({exif_lat:.5f}, {exif_lng:.5f}) were automatically extracted from the image metadata. They will be pre-filled when adding the new location.")
             ^^^^^^^^^^^^^^^^^^^^^^^^^^^^^^^^^^^^^^^^^^^^^^^^^^^^^^^^^^^^^^^^^^^^^^^^^^^^^^^^^^^^^^^^^^^^^^^^^^^^^^^^^^^^^^^^^^^^^^^^^^^^^^^^^^^^^^^^^^^^^^^^^^^^^^^^^^^
ValueError: Unknown format code 'f' for object of type 'str'
2025-06-28 11:52:54.127 Uncaught app execution
Traceback (most recent call last):
  File "/Users/peter/miniforge3/envs/env-streamlit-addaxai/lib/python3.11/site-packages/streamlit/runtime/scriptrunner/exec_code.py", line 121, in exec_func_with_error_handling
    result = func()
             ^^^^^^
  File "/Users/peter/miniforge3/envs/env-streamlit-addaxai/lib/python3.11/site-packages/streamlit/runtime/scriptrunner/script_runner.py", line 645, in code_to_exec
    exec(code, module.__dict__)
  File "/Applications/AddaxAI_files/AddaxAI/streamlit-AddaxAI/frontend/main.py", line 114, in <module>
    from backend.utils import *
  File "/Applications/AddaxAI_files/AddaxAI/streamlit-AddaxAI/backend/utils.py", line 100
    coords_found_in_exif, float(exif_lat), float(exif_lng) = fetch_vars(section="analyse_advanced", # SESSION
                                           ^^^^^^^^^^^^^^^
SyntaxError: cannot assign to function call here. Maybe you meant '==' instead of '='?
2025-06-28 11:54:20.682 Uncaught app execution
Traceback (most recent call last):
  File "/Users/peter/miniforge3/envs/env-streamlit-addaxai/lib/python3.11/site-packages/streamlit/runtime/scriptrunner/exec_code.py", line 121, in exec_func_with_error_handling
    result = func()
             ^^^^^^
  File "/Users/peter/miniforge3/envs/env-streamlit-addaxai/lib/python3.11/site-packages/streamlit/runtime/scriptrunner/script_runner.py", line 645, in code_to_exec
    exec(code, module.__dict__)
  File "/Applications/AddaxAI_files/AddaxAI/streamlit-AddaxAI/frontend/main.py", line 250, in <module>
    pg.run()
  File "/Users/peter/miniforge3/envs/env-streamlit-addaxai/lib/python3.11/site-packages/streamlit/navigation/page.py", line 297, in run
    exec(code, module.__dict__)
  File "/Applications/AddaxAI_files/AddaxAI/streamlit-AddaxAI/frontend/analyse_advanced.py", line 138, in <module>
    selected_locationID = location_selector_widget()
                          ^^^^^^^^^^^^^^^^^^^^^^^^^^
  File "/Applications/AddaxAI_files/AddaxAI/streamlit-AddaxAI/backend/utils.py", line 102, in location_selector_widget
    exif_lat = float(exif_lat) if exif_lat is not None else None
               ^^^^^^^^^^^^^^^
ValueError: could not convert string to float: 'exif_lat'
2025-06-28 11:54:47.694 Uncaught app execution
Traceback (most recent call last):
  File "/Users/peter/miniforge3/envs/env-streamlit-addaxai/lib/python3.11/site-packages/streamlit/runtime/scriptrunner/exec_code.py", line 121, in exec_func_with_error_handling
    result = func()
             ^^^^^^
  File "/Users/peter/miniforge3/envs/env-streamlit-addaxai/lib/python3.11/site-packages/streamlit/runtime/scriptrunner/script_runner.py", line 645, in code_to_exec
    exec(code, module.__dict__)
  File "/Applications/AddaxAI_files/AddaxAI/streamlit-AddaxAI/frontend/main.py", line 250, in <module>
    pg.run()
  File "/Users/peter/miniforge3/envs/env-streamlit-addaxai/lib/python3.11/site-packages/streamlit/navigation/page.py", line 297, in run
    exec(code, module.__dict__)
  File "/Applications/AddaxAI_files/AddaxAI/streamlit-AddaxAI/frontend/analyse_advanced.py", line 138, in <module>
    selected_locationID = location_selector_widget()
                          ^^^^^^^^^^^^^^^^^^^^^^^^^^
  File "/Applications/AddaxAI_files/AddaxAI/streamlit-AddaxAI/backend/utils.py", line 122, in location_selector_widget
    info_box(f"Coordinates ({exif_lat:.5f}, {exif_lng:.5f}) were automatically extracted from the image metadata. They will be pre-filled when adding the new location.")
             ^^^^^^^^^^^^^^^^^^^^^^^^^^^^^^^^^^^^^^^^^^^^^^^^^^^^^^^^^^^^^^^^^^^^^^^^^^^^^^^^^^^^^^^^^^^^^^^^^^^^^^^^^^^^^^^^^^^^^^^^^^^^^^^^^^^^^^^^^^^^^^^^^^^^^^^^^^^
ValueError: Unknown format code 'f' for object of type 'str'
2025-06-28 11:54:47.805 Uncaught app execution
Traceback (most recent call last):
  File "/Users/peter/miniforge3/envs/env-streamlit-addaxai/lib/python3.11/site-packages/streamlit/runtime/scriptrunner/exec_code.py", line 121, in exec_func_with_error_handling
    result = func()
             ^^^^^^
  File "/Users/peter/miniforge3/envs/env-streamlit-addaxai/lib/python3.11/site-packages/streamlit/runtime/scriptrunner/script_runner.py", line 645, in code_to_exec
    exec(code, module.__dict__)
  File "/Applications/AddaxAI_files/AddaxAI/streamlit-AddaxAI/frontend/main.py", line 250, in <module>
    pg.run()
  File "/Users/peter/miniforge3/envs/env-streamlit-addaxai/lib/python3.11/site-packages/streamlit/navigation/page.py", line 297, in run
    exec(code, module.__dict__)
  File "/Applications/AddaxAI_files/AddaxAI/streamlit-AddaxAI/frontend/analyse_advanced.py", line 138, in <module>
    selected_locationID = location_selector_widget()
                          ^^^^^^^^^^^^^^^^^^^^^^^^^^
  File "/Applications/AddaxAI_files/AddaxAI/streamlit-AddaxAI/backend/utils.py", line 122, in location_selector_widget
    info_box(f"Coordinates ({exif_lat:.5f}, {exif_lng:.5f}) were automatically extracted from the image metadata. They will be pre-filled when adding the new location.")
             ^^^^^^^^^^^^^^^^^^^^^^^^^^^^^^^^^^^^^^^^^^^^^^^^^^^^^^^^^^^^^^^^^^^^^^^^^^^^^^^^^^^^^^^^^^^^^^^^^^^^^^^^^^^^^^^^^^^^^^^^^^^^^^^^^^^^^^^^^^^^^^^^^^^^^^^^^^^
ValueError: Unknown format code 'f' for object of type 'str'
2025-06-28 11:55:10.263 Uncaught app execution
Traceback (most recent call last):
  File "/Users/peter/miniforge3/envs/env-streamlit-addaxai/lib/python3.11/site-packages/streamlit/runtime/scriptrunner/exec_code.py", line 121, in exec_func_with_error_handling
    result = func()
             ^^^^^^
  File "/Users/peter/miniforge3/envs/env-streamlit-addaxai/lib/python3.11/site-packages/streamlit/runtime/scriptrunner/script_runner.py", line 645, in code_to_exec
    exec(code, module.__dict__)
  File "/Applications/AddaxAI_files/AddaxAI/streamlit-AddaxAI/frontend/main.py", line 250, in <module>
    pg.run()
  File "/Users/peter/miniforge3/envs/env-streamlit-addaxai/lib/python3.11/site-packages/streamlit/navigation/page.py", line 297, in run
    exec(code, module.__dict__)
  File "/Applications/AddaxAI_files/AddaxAI/streamlit-AddaxAI/frontend/analyse_advanced.py", line 138, in <module>
    selected_locationID = location_selector_widget()
                          ^^^^^^^^^^^^^^^^^^^^^^^^^^
  File "/Applications/AddaxAI_files/AddaxAI/streamlit-AddaxAI/backend/utils.py", line 126, in location_selector_widget
    info_box(f"Coordinates ({exif_lat:.5f}, {exif_lng:.5f}) were automatically extracted from the image metadata. They will be pre-filled when adding the new location.")
             ^^^^^^^^^^^^^^^^^^^^^^^^^^^^^^^^^^^^^^^^^^^^^^^^^^^^^^^^^^^^^^^^^^^^^^^^^^^^^^^^^^^^^^^^^^^^^^^^^^^^^^^^^^^^^^^^^^^^^^^^^^^^^^^^^^^^^^^^^^^^^^^^^^^^^^^^^^^
ValueError: Unknown format code 'f' for object of type 'str'
2025-06-28 11:55:10.363 Uncaught app execution
Traceback (most recent call last):
  File "/Users/peter/miniforge3/envs/env-streamlit-addaxai/lib/python3.11/site-packages/streamlit/runtime/scriptrunner/exec_code.py", line 121, in exec_func_with_error_handling
    result = func()
             ^^^^^^
  File "/Users/peter/miniforge3/envs/env-streamlit-addaxai/lib/python3.11/site-packages/streamlit/runtime/scriptrunner/script_runner.py", line 645, in code_to_exec
    exec(code, module.__dict__)
  File "/Applications/AddaxAI_files/AddaxAI/streamlit-AddaxAI/frontend/main.py", line 250, in <module>
    pg.run()
  File "/Users/peter/miniforge3/envs/env-streamlit-addaxai/lib/python3.11/site-packages/streamlit/navigation/page.py", line 297, in run
    exec(code, module.__dict__)
  File "/Applications/AddaxAI_files/AddaxAI/streamlit-AddaxAI/frontend/analyse_advanced.py", line 138, in <module>
    selected_locationID = location_selector_widget()
                          ^^^^^^^^^^^^^^^^^^^^^^^^^^
  File "/Applications/AddaxAI_files/AddaxAI/streamlit-AddaxAI/backend/utils.py", line 126, in location_selector_widget
    info_box(f"Coordinates ({exif_lat:.5f}, {exif_lng:.5f}) were automatically extracted from the image metadata. They will be pre-filled when adding the new location.")
             ^^^^^^^^^^^^^^^^^^^^^^^^^^^^^^^^^^^^^^^^^^^^^^^^^^^^^^^^^^^^^^^^^^^^^^^^^^^^^^^^^^^^^^^^^^^^^^^^^^^^^^^^^^^^^^^^^^^^^^^^^^^^^^^^^^^^^^^^^^^^^^^^^^^^^^^^^^^
ValueError: Unknown format code 'f' for object of type 'str'
2025-06-28 11:56:53.986 Uncaught app execution
Traceback (most recent call last):
  File "/Users/peter/miniforge3/envs/env-streamlit-addaxai/lib/python3.11/site-packages/streamlit/runtime/scriptrunner/exec_code.py", line 121, in exec_func_with_error_handling
    result = func()
             ^^^^^^
  File "/Users/peter/miniforge3/envs/env-streamlit-addaxai/lib/python3.11/site-packages/streamlit/runtime/scriptrunner/script_runner.py", line 645, in code_to_exec
    exec(code, module.__dict__)
  File "/Applications/AddaxAI_files/AddaxAI/streamlit-AddaxAI/frontend/main.py", line 250, in <module>
    pg.run()
  File "/Users/peter/miniforge3/envs/env-streamlit-addaxai/lib/python3.11/site-packages/streamlit/navigation/page.py", line 297, in run
    exec(code, module.__dict__)
  File "/Applications/AddaxAI_files/AddaxAI/streamlit-AddaxAI/frontend/analyse_advanced.py", line 237, in <module>
    selected_locationID = location_selector_widget()
                          ^^^^^^^^^^^^^^^^^^^^^^^^^^
  File "/Applications/AddaxAI_files/AddaxAI/streamlit-AddaxAI/backend/utils.py", line 120, in location_selector_widget
    add_new_location_popover("Define your first location")
  File "/Applications/AddaxAI_files/AddaxAI/streamlit-AddaxAI/backend/utils.py", line 800, in add_new_location_popover
    add_location(
  File "/Applications/AddaxAI_files/AddaxAI/streamlit-AddaxAI/backend/utils.py", line 513, in add_location
    settings["projects"][project]["locations"] = sorted_locations
    ~~~~~~~~~~~~~~~~~~~~^^^^^^^^^
TypeError: unhashable type: 'dict'
2025-06-28 12:06:18.918 Uncaught app execution
Traceback (most recent call last):
  File "/Users/peter/miniforge3/envs/env-streamlit-addaxai/lib/python3.11/site-packages/streamlit/runtime/scriptrunner/exec_code.py", line 121, in exec_func_with_error_handling
    result = func()
             ^^^^^^
  File "/Users/peter/miniforge3/envs/env-streamlit-addaxai/lib/python3.11/site-packages/streamlit/runtime/scriptrunner/script_runner.py", line 645, in code_to_exec
    exec(code, module.__dict__)
  File "/Applications/AddaxAI_files/AddaxAI/streamlit-AddaxAI/frontend/main.py", line 250, in <module>
    pg.run()
  File "/Users/peter/miniforge3/envs/env-streamlit-addaxai/lib/python3.11/site-packages/streamlit/navigation/page.py", line 297, in run
    exec(code, module.__dict__)
  File "/Applications/AddaxAI_files/AddaxAI/streamlit-AddaxAI/frontend/analyse_advanced.py", line 138, in <module>
    selected_locationID = location_selector_widget()
                          ^^^^^^^^^^^^^^^^^^^^^^^^^^
  File "/Applications/AddaxAI_files/AddaxAI/streamlit-AddaxAI/backend/utils.py", line 127, in location_selector_widget
    add_new_location_popover("Define your first location")
  File "/Applications/AddaxAI_files/AddaxAI/streamlit-AddaxAI/backend/utils.py", line 825, in add_new_location_popover
    old_lat = get("lat_selected", 0.0)
              ^^^
NameError: name 'get' is not defined
2025-06-28 12:06:19.132 Uncaught app execution
Traceback (most recent call last):
  File "/Users/peter/miniforge3/envs/env-streamlit-addaxai/lib/python3.11/site-packages/streamlit/runtime/scriptrunner/exec_code.py", line 121, in exec_func_with_error_handling
    result = func()
             ^^^^^^
  File "/Users/peter/miniforge3/envs/env-streamlit-addaxai/lib/python3.11/site-packages/streamlit/runtime/scriptrunner/script_runner.py", line 645, in code_to_exec
    exec(code, module.__dict__)
  File "/Applications/AddaxAI_files/AddaxAI/streamlit-AddaxAI/frontend/main.py", line 250, in <module>
    pg.run()
  File "/Users/peter/miniforge3/envs/env-streamlit-addaxai/lib/python3.11/site-packages/streamlit/navigation/page.py", line 297, in run
    exec(code, module.__dict__)
  File "/Applications/AddaxAI_files/AddaxAI/streamlit-AddaxAI/frontend/analyse_advanced.py", line 138, in <module>
    selected_locationID = location_selector_widget()
                          ^^^^^^^^^^^^^^^^^^^^^^^^^^
  File "/Applications/AddaxAI_files/AddaxAI/streamlit-AddaxAI/backend/utils.py", line 127, in location_selector_widget
    add_new_location_popover("Define your first location")
  File "/Applications/AddaxAI_files/AddaxAI/streamlit-AddaxAI/backend/utils.py", line 825, in add_new_location_popover
    old_lat = get("lat_selected", 0.0)
              ^^^
NameError: name 'get' is not defined
2025-06-28 12:06:19.676 Uncaught app execution
Traceback (most recent call last):
  File "/Users/peter/miniforge3/envs/env-streamlit-addaxai/lib/python3.11/site-packages/streamlit/runtime/scriptrunner/exec_code.py", line 121, in exec_func_with_error_handling
    result = func()
             ^^^^^^
  File "/Users/peter/miniforge3/envs/env-streamlit-addaxai/lib/python3.11/site-packages/streamlit/runtime/scriptrunner/script_runner.py", line 645, in code_to_exec
    exec(code, module.__dict__)
  File "/Applications/AddaxAI_files/AddaxAI/streamlit-AddaxAI/frontend/main.py", line 250, in <module>
    pg.run()
  File "/Users/peter/miniforge3/envs/env-streamlit-addaxai/lib/python3.11/site-packages/streamlit/navigation/page.py", line 297, in run
    exec(code, module.__dict__)
  File "/Applications/AddaxAI_files/AddaxAI/streamlit-AddaxAI/frontend/analyse_advanced.py", line 138, in <module>
    selected_locationID = location_selector_widget()
                          ^^^^^^^^^^^^^^^^^^^^^^^^^^
  File "/Applications/AddaxAI_files/AddaxAI/streamlit-AddaxAI/backend/utils.py", line 127, in location_selector_widget
    add_new_location_popover("Define your first location")
  File "/Applications/AddaxAI_files/AddaxAI/streamlit-AddaxAI/backend/utils.py", line 825, in add_new_location_popover
    old_lat = get("lat_selected", 0.0)
              ^^^
NameError: name 'get' is not defined
2025-06-28 12:06:20.978 Uncaught app execution
Traceback (most recent call last):
  File "/Users/peter/miniforge3/envs/env-streamlit-addaxai/lib/python3.11/site-packages/streamlit/runtime/scriptrunner/exec_code.py", line 121, in exec_func_with_error_handling
    result = func()
             ^^^^^^
  File "/Users/peter/miniforge3/envs/env-streamlit-addaxai/lib/python3.11/site-packages/streamlit/runtime/scriptrunner/script_runner.py", line 645, in code_to_exec
    exec(code, module.__dict__)
  File "/Applications/AddaxAI_files/AddaxAI/streamlit-AddaxAI/frontend/main.py", line 250, in <module>
    pg.run()
  File "/Users/peter/miniforge3/envs/env-streamlit-addaxai/lib/python3.11/site-packages/streamlit/navigation/page.py", line 297, in run
    exec(code, module.__dict__)
  File "/Applications/AddaxAI_files/AddaxAI/streamlit-AddaxAI/frontend/analyse_advanced.py", line 138, in <module>
    selected_locationID = location_selector_widget()
                          ^^^^^^^^^^^^^^^^^^^^^^^^^^
  File "/Applications/AddaxAI_files/AddaxAI/streamlit-AddaxAI/backend/utils.py", line 127, in location_selector_widget
    add_new_location_popover("Define your first location")
  File "/Applications/AddaxAI_files/AddaxAI/streamlit-AddaxAI/backend/utils.py", line 825, in add_new_location_popover
    old_lat = get("lat_selected", 0.0)
              ^^^
NameError: name 'get' is not defined
2025-06-28 12:06:23.018 Uncaught app execution
Traceback (most recent call last):
  File "/Users/peter/miniforge3/envs/env-streamlit-addaxai/lib/python3.11/site-packages/streamlit/runtime/scriptrunner/exec_code.py", line 121, in exec_func_with_error_handling
    result = func()
             ^^^^^^
  File "/Users/peter/miniforge3/envs/env-streamlit-addaxai/lib/python3.11/site-packages/streamlit/runtime/scriptrunner/script_runner.py", line 645, in code_to_exec
    exec(code, module.__dict__)
  File "/Applications/AddaxAI_files/AddaxAI/streamlit-AddaxAI/frontend/main.py", line 250, in <module>
    pg.run()
  File "/Users/peter/miniforge3/envs/env-streamlit-addaxai/lib/python3.11/site-packages/streamlit/navigation/page.py", line 297, in run
    exec(code, module.__dict__)
  File "/Applications/AddaxAI_files/AddaxAI/streamlit-AddaxAI/frontend/analyse_advanced.py", line 138, in <module>
    selected_locationID = location_selector_widget()
                          ^^^^^^^^^^^^^^^^^^^^^^^^^^
  File "/Applications/AddaxAI_files/AddaxAI/streamlit-AddaxAI/backend/utils.py", line 127, in location_selector_widget
    add_new_location_popover("Define your first location")
  File "/Applications/AddaxAI_files/AddaxAI/streamlit-AddaxAI/backend/utils.py", line 825, in add_new_location_popover
    old_lat = get("lat_selected", 0.0)
              ^^^
NameError: name 'get' is not defined
2025-06-28 12:06:23.217 Uncaught app execution
Traceback (most recent call last):
  File "/Users/peter/miniforge3/envs/env-streamlit-addaxai/lib/python3.11/site-packages/streamlit/runtime/scriptrunner/exec_code.py", line 121, in exec_func_with_error_handling
    result = func()
             ^^^^^^
  File "/Users/peter/miniforge3/envs/env-streamlit-addaxai/lib/python3.11/site-packages/streamlit/runtime/scriptrunner/script_runner.py", line 645, in code_to_exec
    exec(code, module.__dict__)
  File "/Applications/AddaxAI_files/AddaxAI/streamlit-AddaxAI/frontend/main.py", line 250, in <module>
    pg.run()
  File "/Users/peter/miniforge3/envs/env-streamlit-addaxai/lib/python3.11/site-packages/streamlit/navigation/page.py", line 297, in run
    exec(code, module.__dict__)
  File "/Applications/AddaxAI_files/AddaxAI/streamlit-AddaxAI/frontend/analyse_advanced.py", line 138, in <module>
    selected_locationID = location_selector_widget()
                          ^^^^^^^^^^^^^^^^^^^^^^^^^^
  File "/Applications/AddaxAI_files/AddaxAI/streamlit-AddaxAI/backend/utils.py", line 127, in location_selector_widget
    add_new_location_popover("Define your first location")
  File "/Applications/AddaxAI_files/AddaxAI/streamlit-AddaxAI/backend/utils.py", line 825, in add_new_location_popover
    old_lat = get("lat_selected", 0.0)
              ^^^
NameError: name 'get' is not defined
2025-06-28 12:06:28.293 Uncaught app execution
Traceback (most recent call last):
  File "/Users/peter/miniforge3/envs/env-streamlit-addaxai/lib/python3.11/site-packages/streamlit/runtime/scriptrunner/exec_code.py", line 121, in exec_func_with_error_handling
    result = func()
             ^^^^^^
  File "/Users/peter/miniforge3/envs/env-streamlit-addaxai/lib/python3.11/site-packages/streamlit/runtime/scriptrunner/script_runner.py", line 645, in code_to_exec
    exec(code, module.__dict__)
  File "/Applications/AddaxAI_files/AddaxAI/streamlit-AddaxAI/frontend/main.py", line 250, in <module>
    pg.run()
  File "/Users/peter/miniforge3/envs/env-streamlit-addaxai/lib/python3.11/site-packages/streamlit/navigation/page.py", line 297, in run
    exec(code, module.__dict__)
  File "/Applications/AddaxAI_files/AddaxAI/streamlit-AddaxAI/frontend/analyse_advanced.py", line 138, in <module>
    selected_locationID = location_selector_widget()
                          ^^^^^^^^^^^^^^^^^^^^^^^^^^
  File "/Applications/AddaxAI_files/AddaxAI/streamlit-AddaxAI/backend/utils.py", line 127, in location_selector_widget
    add_new_location_popover("Define your first location")
  File "/Applications/AddaxAI_files/AddaxAI/streamlit-AddaxAI/backend/utils.py", line 825, in add_new_location_popover
    old_lat = get("lat_selected", 0.0)
              ^^^
NameError: name 'get' is not defined
2025-06-28 12:06:28.790 Uncaught app execution
Traceback (most recent call last):
  File "/Users/peter/miniforge3/envs/env-streamlit-addaxai/lib/python3.11/site-packages/streamlit/runtime/scriptrunner/exec_code.py", line 121, in exec_func_with_error_handling
    result = func()
             ^^^^^^
  File "/Users/peter/miniforge3/envs/env-streamlit-addaxai/lib/python3.11/site-packages/streamlit/runtime/scriptrunner/script_runner.py", line 645, in code_to_exec
    exec(code, module.__dict__)
  File "/Applications/AddaxAI_files/AddaxAI/streamlit-AddaxAI/frontend/main.py", line 250, in <module>
    pg.run()
  File "/Users/peter/miniforge3/envs/env-streamlit-addaxai/lib/python3.11/site-packages/streamlit/navigation/page.py", line 297, in run
    exec(code, module.__dict__)
  File "/Applications/AddaxAI_files/AddaxAI/streamlit-AddaxAI/frontend/analyse_advanced.py", line 138, in <module>
    selected_locationID = location_selector_widget()
                          ^^^^^^^^^^^^^^^^^^^^^^^^^^
  File "/Applications/AddaxAI_files/AddaxAI/streamlit-AddaxAI/backend/utils.py", line 127, in location_selector_widget
    add_new_location_popover("Define your first location")
  File "/Applications/AddaxAI_files/AddaxAI/streamlit-AddaxAI/backend/utils.py", line 825, in add_new_location_popover
    old_lat = get("lat_selected", 0.0)
              ^^^
NameError: name 'get' is not defined
2025-06-28 12:06:30.934 Uncaught app execution
Traceback (most recent call last):
  File "/Users/peter/miniforge3/envs/env-streamlit-addaxai/lib/python3.11/site-packages/streamlit/runtime/scriptrunner/exec_code.py", line 121, in exec_func_with_error_handling
    result = func()
             ^^^^^^
  File "/Users/peter/miniforge3/envs/env-streamlit-addaxai/lib/python3.11/site-packages/streamlit/runtime/scriptrunner/script_runner.py", line 645, in code_to_exec
    exec(code, module.__dict__)
  File "/Applications/AddaxAI_files/AddaxAI/streamlit-AddaxAI/frontend/main.py", line 250, in <module>
    pg.run()
  File "/Users/peter/miniforge3/envs/env-streamlit-addaxai/lib/python3.11/site-packages/streamlit/navigation/page.py", line 297, in run
    exec(code, module.__dict__)
  File "/Applications/AddaxAI_files/AddaxAI/streamlit-AddaxAI/frontend/analyse_advanced.py", line 138, in <module>
    selected_locationID = location_selector_widget()
                          ^^^^^^^^^^^^^^^^^^^^^^^^^^
  File "/Applications/AddaxAI_files/AddaxAI/streamlit-AddaxAI/backend/utils.py", line 127, in location_selector_widget
    add_new_location_popover("Define your first location")
  File "/Applications/AddaxAI_files/AddaxAI/streamlit-AddaxAI/backend/utils.py", line 825, in add_new_location_popover
    old_lat = get("lat_selected", 0.0)
              ^^^
NameError: name 'get' is not defined
2025-06-28 12:10:01.887 Uncaught app execution
Traceback (most recent call last):
  File "/Users/peter/miniforge3/envs/env-streamlit-addaxai/lib/python3.11/site-packages/streamlit/runtime/state/session_state.py", line 454, in __getitem__
    return self._getitem(widget_id, key)
           ^^^^^^^^^^^^^^^^^^^^^^^^^^^^^
  File "/Users/peter/miniforge3/envs/env-streamlit-addaxai/lib/python3.11/site-packages/streamlit/runtime/state/session_state.py", line 499, in _getitem
    raise KeyError
KeyError

During handling of the above exception, another exception occurred:

Traceback (most recent call last):
  File "/Users/peter/miniforge3/envs/env-streamlit-addaxai/lib/python3.11/site-packages/streamlit/runtime/state/session_state_proxy.py", line 130, in __getattr__
    return self[key]
           ~~~~^^^^^
  File "/Users/peter/miniforge3/envs/env-streamlit-addaxai/lib/python3.11/site-packages/streamlit/runtime/state/session_state_proxy.py", line 101, in __getitem__
    return get_session_state()[key]
           ~~~~~~~~~~~~~~~~~~~^^^^^
  File "/Users/peter/miniforge3/envs/env-streamlit-addaxai/lib/python3.11/site-packages/streamlit/runtime/state/safe_session_state.py", line 96, in __getitem__
    return self._state[key]
           ~~~~~~~~~~~^^^^^
  File "/Users/peter/miniforge3/envs/env-streamlit-addaxai/lib/python3.11/site-packages/streamlit/runtime/state/session_state.py", line 456, in __getitem__
    raise KeyError(_missing_key_error_message(key))
KeyError: 'st.session_state has no key "lat_selected". Did you forget to initialize it? More info: https://docs.streamlit.io/develop/concepts/architecture/session-state#initialization'

During handling of the above exception, another exception occurred:

Traceback (most recent call last):
  File "/Users/peter/miniforge3/envs/env-streamlit-addaxai/lib/python3.11/site-packages/streamlit/runtime/scriptrunner/exec_code.py", line 121, in exec_func_with_error_handling
    result = func()
             ^^^^^^
  File "/Users/peter/miniforge3/envs/env-streamlit-addaxai/lib/python3.11/site-packages/streamlit/runtime/scriptrunner/script_runner.py", line 645, in code_to_exec
    exec(code, module.__dict__)
  File "/Applications/AddaxAI_files/AddaxAI/streamlit-AddaxAI/frontend/main.py", line 250, in <module>
    pg.run()
  File "/Users/peter/miniforge3/envs/env-streamlit-addaxai/lib/python3.11/site-packages/streamlit/navigation/page.py", line 297, in run
    exec(code, module.__dict__)
  File "/Applications/AddaxAI_files/AddaxAI/streamlit-AddaxAI/frontend/analyse_advanced.py", line 138, in <module>
    selected_locationID = location_selector_widget()
                          ^^^^^^^^^^^^^^^^^^^^^^^^^^
  File "/Applications/AddaxAI_files/AddaxAI/streamlit-AddaxAI/backend/utils.py", line 127, in location_selector_widget
    add_new_location_popover("Define your first location")
  File "/Applications/AddaxAI_files/AddaxAI/streamlit-AddaxAI/backend/utils.py", line 767, in add_new_location_popover
    if st.session_state.lat_selected and st.session_state.lng_selected:
       ^^^^^^^^^^^^^^^^^^^^^^^^^^^^^
  File "/Users/peter/miniforge3/envs/env-streamlit-addaxai/lib/python3.11/site-packages/streamlit/runtime/state/session_state_proxy.py", line 132, in __getattr__
    raise AttributeError(_missing_attr_error_message(key))
AttributeError: st.session_state has no attribute "lat_selected". Did you forget to initialize it? More info: https://docs.streamlit.io/develop/concepts/architecture/session-state#initialization
2025-06-28 12:11:26.199 Uncaught app execution
Traceback (most recent call last):
  File "/Users/peter/miniforge3/envs/env-streamlit-addaxai/lib/python3.11/site-packages/streamlit/runtime/state/session_state.py", line 454, in __getitem__
    return self._getitem(widget_id, key)
           ^^^^^^^^^^^^^^^^^^^^^^^^^^^^^
  File "/Users/peter/miniforge3/envs/env-streamlit-addaxai/lib/python3.11/site-packages/streamlit/runtime/state/session_state.py", line 499, in _getitem
    raise KeyError
KeyError

During handling of the above exception, another exception occurred:

Traceback (most recent call last):
  File "/Users/peter/miniforge3/envs/env-streamlit-addaxai/lib/python3.11/site-packages/streamlit/runtime/state/session_state_proxy.py", line 130, in __getattr__
    return self[key]
           ~~~~^^^^^
  File "/Users/peter/miniforge3/envs/env-streamlit-addaxai/lib/python3.11/site-packages/streamlit/runtime/state/session_state_proxy.py", line 101, in __getitem__
    return get_session_state()[key]
           ~~~~~~~~~~~~~~~~~~~^^^^^
  File "/Users/peter/miniforge3/envs/env-streamlit-addaxai/lib/python3.11/site-packages/streamlit/runtime/state/safe_session_state.py", line 96, in __getitem__
    return self._state[key]
           ~~~~~~~~~~~^^^^^
  File "/Users/peter/miniforge3/envs/env-streamlit-addaxai/lib/python3.11/site-packages/streamlit/runtime/state/session_state.py", line 456, in __getitem__
    raise KeyError(_missing_key_error_message(key))
KeyError: 'st.session_state has no key "lat_selected". Did you forget to initialize it? More info: https://docs.streamlit.io/develop/concepts/architecture/session-state#initialization'

During handling of the above exception, another exception occurred:

Traceback (most recent call last):
  File "/Users/peter/miniforge3/envs/env-streamlit-addaxai/lib/python3.11/site-packages/streamlit/runtime/scriptrunner/exec_code.py", line 121, in exec_func_with_error_handling
    result = func()
             ^^^^^^
  File "/Users/peter/miniforge3/envs/env-streamlit-addaxai/lib/python3.11/site-packages/streamlit/runtime/scriptrunner/script_runner.py", line 645, in code_to_exec
    exec(code, module.__dict__)
  File "/Applications/AddaxAI_files/AddaxAI/streamlit-AddaxAI/frontend/main.py", line 250, in <module>
    pg.run()
  File "/Users/peter/miniforge3/envs/env-streamlit-addaxai/lib/python3.11/site-packages/streamlit/navigation/page.py", line 297, in run
    exec(code, module.__dict__)
  File "/Applications/AddaxAI_files/AddaxAI/streamlit-AddaxAI/frontend/analyse_advanced.py", line 138, in <module>
    selected_locationID = location_selector_widget()
                          ^^^^^^^^^^^^^^^^^^^^^^^^^^
  File "/Applications/AddaxAI_files/AddaxAI/streamlit-AddaxAI/backend/utils.py", line 127, in location_selector_widget
    add_new_location_popover("Define your first location")
  File "/Applications/AddaxAI_files/AddaxAI/streamlit-AddaxAI/backend/utils.py", line 767, in add_new_location_popover
    m.fit_bounds(bounds, padding=(75, 75))
    ^^^^^^^^^^^^^^^^^^^^^^^^^^^^^
  File "/Users/peter/miniforge3/envs/env-streamlit-addaxai/lib/python3.11/site-packages/streamlit/runtime/state/session_state_proxy.py", line 132, in __getattr__
    raise AttributeError(_missing_attr_error_message(key))
AttributeError: st.session_state has no attribute "lat_selected". Did you forget to initialize it? More info: https://docs.streamlit.io/develop/concepts/architecture/session-state#initialization
2025-06-28 13:23:54.205 Uncaught app execution
Traceback (most recent call last):
  File "/Users/peter/miniforge3/envs/env-streamlit-addaxai/lib/python3.11/site-packages/streamlit/runtime/scriptrunner/exec_code.py", line 121, in exec_func_with_error_handling
    result = func()
             ^^^^^^
  File "/Users/peter/miniforge3/envs/env-streamlit-addaxai/lib/python3.11/site-packages/streamlit/runtime/scriptrunner/script_runner.py", line 645, in code_to_exec
    exec(code, module.__dict__)
  File "/Applications/AddaxAI_files/AddaxAI/streamlit-AddaxAI/frontend/main.py", line 250, in <module>
    pg.run()
  File "/Users/peter/miniforge3/envs/env-streamlit-addaxai/lib/python3.11/site-packages/streamlit/navigation/page.py", line 297, in run
    exec(code, module.__dict__)
  File "/Applications/AddaxAI_files/AddaxAI/streamlit-AddaxAI/frontend/analyse_advanced.py", line 138, in <module>
    selected_locationID = location_selector_widget()
                          ^^^^^^^^^^^^^^^^^^^^^^^^^^
  File "/Applications/AddaxAI_files/AddaxAI/streamlit-AddaxAI/backend/utils.py", line 127, in location_selector_widget
    add_new_location_popover("Define your first location")
  File "/Applications/AddaxAI_files/AddaxAI/streamlit-AddaxAI/backend/utils.py", line 884, in add_new_location_popover
    add_location(
  File "/Applications/AddaxAI_files/AddaxAI/streamlit-AddaxAI/backend/utils.py", line 564, in add_location
    settings["projects"][project]["locations"] = sorted_locations
    ~~~~~~~~~~~~~~~~~~~~^^^^^^^^^
TypeError: unhashable type: 'dict'
2025-06-28 13:24:04.931 Uncaught app execution
Traceback (most recent call last):
  File "/Users/peter/miniforge3/envs/env-streamlit-addaxai/lib/python3.11/site-packages/streamlit/runtime/scriptrunner/exec_code.py", line 121, in exec_func_with_error_handling
    result = func()
             ^^^^^^
  File "/Users/peter/miniforge3/envs/env-streamlit-addaxai/lib/python3.11/site-packages/streamlit/runtime/scriptrunner/script_runner.py", line 645, in code_to_exec
    exec(code, module.__dict__)
  File "/Applications/AddaxAI_files/AddaxAI/streamlit-AddaxAI/frontend/main.py", line 250, in <module>
    pg.run()
  File "/Users/peter/miniforge3/envs/env-streamlit-addaxai/lib/python3.11/site-packages/streamlit/navigation/page.py", line 297, in run
    exec(code, module.__dict__)
  File "/Applications/AddaxAI_files/AddaxAI/streamlit-AddaxAI/frontend/analyse_advanced.py", line 138, in <module>
    selected_locationID = location_selector_widget()
                          ^^^^^^^^^^^^^^^^^^^^^^^^^^
  File "/Applications/AddaxAI_files/AddaxAI/streamlit-AddaxAI/backend/utils.py", line 127, in location_selector_widget
    add_new_location_popover("Define your first location")
  File "/Applications/AddaxAI_files/AddaxAI/streamlit-AddaxAI/backend/utils.py", line 884, in add_new_location_popover
    add_location(
  File "/Applications/AddaxAI_files/AddaxAI/streamlit-AddaxAI/backend/utils.py", line 564, in add_location
    settings["projects"][project]["locations"] = sorted_locations
    ~~~~~~~~~~~~~~~~~~~~^^^^^^^^^
TypeError: unhashable type: 'dict'
2025-06-28 13:24:12.511 Uncaught app execution
Traceback (most recent call last):
  File "/Users/peter/miniforge3/envs/env-streamlit-addaxai/lib/python3.11/site-packages/streamlit/runtime/scriptrunner/exec_code.py", line 121, in exec_func_with_error_handling
    result = func()
             ^^^^^^
  File "/Users/peter/miniforge3/envs/env-streamlit-addaxai/lib/python3.11/site-packages/streamlit/runtime/scriptrunner/script_runner.py", line 645, in code_to_exec
    exec(code, module.__dict__)
  File "/Applications/AddaxAI_files/AddaxAI/streamlit-AddaxAI/frontend/main.py", line 250, in <module>
    pg.run()
  File "/Users/peter/miniforge3/envs/env-streamlit-addaxai/lib/python3.11/site-packages/streamlit/navigation/page.py", line 297, in run
    exec(code, module.__dict__)
  File "/Applications/AddaxAI_files/AddaxAI/streamlit-AddaxAI/frontend/analyse_advanced.py", line 138, in <module>
    selected_locationID = location_selector_widget()
                          ^^^^^^^^^^^^^^^^^^^^^^^^^^
  File "/Applications/AddaxAI_files/AddaxAI/streamlit-AddaxAI/backend/utils.py", line 127, in location_selector_widget
    add_new_location_popover("Define your first location")
  File "/Applications/AddaxAI_files/AddaxAI/streamlit-AddaxAI/backend/utils.py", line 884, in add_new_location_popover
    add_location(
  File "/Applications/AddaxAI_files/AddaxAI/streamlit-AddaxAI/backend/utils.py", line 564, in add_location
    settings["projects"][project]["locations"] = sorted_locations
    ~~~~~~~~~~~~~~~~~~~~^^^^^^^^^
TypeError: unhashable type: 'dict'
2025-06-28 13:24:28.642 Uncaught app execution
Traceback (most recent call last):
  File "/Users/peter/miniforge3/envs/env-streamlit-addaxai/lib/python3.11/site-packages/streamlit/runtime/scriptrunner/exec_code.py", line 121, in exec_func_with_error_handling
    result = func()
             ^^^^^^
  File "/Users/peter/miniforge3/envs/env-streamlit-addaxai/lib/python3.11/site-packages/streamlit/runtime/scriptrunner/script_runner.py", line 645, in code_to_exec
    exec(code, module.__dict__)
  File "/Applications/AddaxAI_files/AddaxAI/streamlit-AddaxAI/frontend/main.py", line 250, in <module>
    pg.run()
  File "/Users/peter/miniforge3/envs/env-streamlit-addaxai/lib/python3.11/site-packages/streamlit/navigation/page.py", line 297, in run
    exec(code, module.__dict__)
  File "/Applications/AddaxAI_files/AddaxAI/streamlit-AddaxAI/frontend/analyse_advanced.py", line 138, in <module>
    selected_locationID = location_selector_widget()
                          ^^^^^^^^^^^^^^^^^^^^^^^^^^
  File "/Applications/AddaxAI_files/AddaxAI/streamlit-AddaxAI/backend/utils.py", line 127, in location_selector_widget
    add_new_location_popover("Define your first location")
  File "/Applications/AddaxAI_files/AddaxAI/streamlit-AddaxAI/backend/utils.py", line 884, in add_new_location_popover
    add_location(
  File "/Applications/AddaxAI_files/AddaxAI/streamlit-AddaxAI/backend/utils.py", line 564, in add_location
    settings["projects"][project]["locations"] = sorted_locations
    ~~~~~~~~~~~~~~~~~~~~^^^^^^^^^
TypeError: unhashable type: 'dict'
2025-06-28 13:26:02.622 Uncaught app execution
Traceback (most recent call last):
  File "/Users/peter/miniforge3/envs/env-streamlit-addaxai/lib/python3.11/site-packages/streamlit/runtime/scriptrunner/exec_code.py", line 121, in exec_func_with_error_handling
    result = func()
             ^^^^^^
  File "/Users/peter/miniforge3/envs/env-streamlit-addaxai/lib/python3.11/site-packages/streamlit/runtime/scriptrunner/script_runner.py", line 645, in code_to_exec
    exec(code, module.__dict__)
  File "/Applications/AddaxAI_files/AddaxAI/streamlit-AddaxAI/frontend/main.py", line 250, in <module>
    pg.run()
  File "/Users/peter/miniforge3/envs/env-streamlit-addaxai/lib/python3.11/site-packages/streamlit/navigation/page.py", line 297, in run
    exec(code, module.__dict__)
  File "/Applications/AddaxAI_files/AddaxAI/streamlit-AddaxAI/frontend/settings.py", line 11, in <module>
    lang = settings["lang"]
           ~~~~~~~~^^^^^^^^
KeyError: 'lang'
2025-06-28 13:35:41.429 Uncaught app execution
Traceback (most recent call last):
  File "/Users/peter/miniforge3/envs/env-streamlit-addaxai/lib/python3.11/site-packages/streamlit/runtime/scriptrunner/exec_code.py", line 121, in exec_func_with_error_handling
    result = func()
             ^^^^^^
  File "/Users/peter/miniforge3/envs/env-streamlit-addaxai/lib/python3.11/site-packages/streamlit/runtime/scriptrunner/script_runner.py", line 645, in code_to_exec
    exec(code, module.__dict__)
  File "/Applications/AddaxAI_files/AddaxAI/streamlit-AddaxAI/frontend/main.py", line 250, in <module>
    pg.run()
  File "/Users/peter/miniforge3/envs/env-streamlit-addaxai/lib/python3.11/site-packages/streamlit/navigation/page.py", line 297, in run
    exec(code, module.__dict__)
  File "/Applications/AddaxAI_files/AddaxAI/streamlit-AddaxAI/frontend/analyse_advanced.py", line 162, in <module>
    add_deployment(selected_datetime)
  File "/Applications/AddaxAI_files/AddaxAI/streamlit-AddaxAI/backend/utils.py", line 515, in add_deployment
    selected_folder = settings["selected_folder"]
                      ~~~~~~~~^^^^^^^^^^^^^^^^^^^
KeyError: 'selected_folder'
2025-06-28 13:36:26.988 Uncaught app execution
Traceback (most recent call last):
  File "/Users/peter/miniforge3/envs/env-streamlit-addaxai/lib/python3.11/site-packages/streamlit/runtime/scriptrunner/exec_code.py", line 121, in exec_func_with_error_handling
    result = func()
             ^^^^^^
  File "/Users/peter/miniforge3/envs/env-streamlit-addaxai/lib/python3.11/site-packages/streamlit/runtime/scriptrunner/script_runner.py", line 645, in code_to_exec
    exec(code, module.__dict__)
  File "/Applications/AddaxAI_files/AddaxAI/streamlit-AddaxAI/frontend/main.py", line 250, in <module>
    pg.run()
  File "/Users/peter/miniforge3/envs/env-streamlit-addaxai/lib/python3.11/site-packages/streamlit/navigation/page.py", line 297, in run
    exec(code, module.__dict__)
  File "/Applications/AddaxAI_files/AddaxAI/streamlit-AddaxAI/frontend/analyse_advanced.py", line 162, in <module>
    add_deployment(selected_datetime)
  File "/Applications/AddaxAI_files/AddaxAI/streamlit-AddaxAI/backend/utils.py", line 516, in add_deployment
    selected_folder = settings["vars"]["analyse_advaced"]["selected_folder"]
                      ~~~~~~~~~~~~~~~~^^^^^^^^^^^^^^^^^^^
KeyError: 'analyse_advaced'
2025-06-28 13:36:50.137 Uncaught app execution
Traceback (most recent call last):
  File "/Users/peter/miniforge3/envs/env-streamlit-addaxai/lib/python3.11/site-packages/streamlit/runtime/scriptrunner/exec_code.py", line 121, in exec_func_with_error_handling
    result = func()
             ^^^^^^
  File "/Users/peter/miniforge3/envs/env-streamlit-addaxai/lib/python3.11/site-packages/streamlit/runtime/scriptrunner/script_runner.py", line 645, in code_to_exec
    exec(code, module.__dict__)
  File "/Applications/AddaxAI_files/AddaxAI/streamlit-AddaxAI/frontend/main.py", line 250, in <module>
    pg.run()
  File "/Users/peter/miniforge3/envs/env-streamlit-addaxai/lib/python3.11/site-packages/streamlit/navigation/page.py", line 297, in run
    exec(code, module.__dict__)
  File "/Applications/AddaxAI_files/AddaxAI/streamlit-AddaxAI/frontend/analyse_advanced.py", line 162, in <module>
    add_deployment(selected_datetime)
  File "/Applications/AddaxAI_files/AddaxAI/streamlit-AddaxAI/backend/utils.py", line 521, in add_deployment
    location = project["location"]
               ~~~~~~~^^^^^^^^^^^^
KeyError: 'location'
2025-06-28 13:40:01.426 Uncaught app execution
Traceback (most recent call last):
  File "/Users/peter/miniforge3/envs/env-streamlit-addaxai/lib/python3.11/site-packages/streamlit/runtime/scriptrunner/exec_code.py", line 121, in exec_func_with_error_handling
    result = func()
             ^^^^^^
  File "/Users/peter/miniforge3/envs/env-streamlit-addaxai/lib/python3.11/site-packages/streamlit/runtime/scriptrunner/script_runner.py", line 645, in code_to_exec
    exec(code, module.__dict__)
  File "/Applications/AddaxAI_files/AddaxAI/streamlit-AddaxAI/frontend/main.py", line 250, in <module>
    pg.run()
  File "/Users/peter/miniforge3/envs/env-streamlit-addaxai/lib/python3.11/site-packages/streamlit/navigation/page.py", line 297, in run
    exec(code, module.__dict__)
  File "/Applications/AddaxAI_files/AddaxAI/streamlit-AddaxAI/frontend/analyse_advanced.py", line 162, in <module>
    add_deployment(selected_datetime)
  File "/Applications/AddaxAI_files/AddaxAI/streamlit-AddaxAI/backend/utils.py", line 533, in add_deployment
    location = project["locations"][selected_locationID]
               ~~~~~~~~~~~~~~~~~~~~^^^^^^^^^^^^^^^^^^^^^
KeyError: None
2025-06-28 13:40:31.296 Uncaught app execution
Traceback (most recent call last):
  File "/Users/peter/miniforge3/envs/env-streamlit-addaxai/lib/python3.11/site-packages/streamlit/runtime/scriptrunner/exec_code.py", line 121, in exec_func_with_error_handling
    result = func()
             ^^^^^^
  File "/Users/peter/miniforge3/envs/env-streamlit-addaxai/lib/python3.11/site-packages/streamlit/runtime/scriptrunner/script_runner.py", line 645, in code_to_exec
    exec(code, module.__dict__)
  File "/Applications/AddaxAI_files/AddaxAI/streamlit-AddaxAI/frontend/main.py", line 250, in <module>
    pg.run()
  File "/Users/peter/miniforge3/envs/env-streamlit-addaxai/lib/python3.11/site-packages/streamlit/navigation/page.py", line 297, in run
    exec(code, module.__dict__)
  File "/Applications/AddaxAI_files/AddaxAI/streamlit-AddaxAI/frontend/analyse_advanced.py", line 162, in <module>
    add_deployment(selected_datetime)
  File "/Applications/AddaxAI_files/AddaxAI/streamlit-AddaxAI/backend/utils.py", line 534, in add_deployment
    location = project["locations"][selected_locationID]
               ~~~~~~~~~~~~~~~~~~~~^^^^^^^^^^^^^^^^^^^^^
KeyError: None
2025-06-30 11:22:27.617 Uncaught app execution
Traceback (most recent call last):
  File "/Users/peter/miniforge3/envs/env-streamlit-addaxai/lib/python3.11/site-packages/streamlit/runtime/scriptrunner/exec_code.py", line 121, in exec_func_with_error_handling
    result = func()
             ^^^^^^
  File "/Users/peter/miniforge3/envs/env-streamlit-addaxai/lib/python3.11/site-packages/streamlit/runtime/scriptrunner/script_runner.py", line 645, in code_to_exec
    exec(code, module.__dict__)
  File "/Applications/AddaxAI_files/AddaxAI/streamlit-AddaxAI/frontend/main.py", line 250, in <module>
    pg.run()
  File "/Users/peter/miniforge3/envs/env-streamlit-addaxai/lib/python3.11/site-packages/streamlit/navigation/page.py", line 297, in run
    exec(code, module.__dict__)
  File "/Applications/AddaxAI_files/AddaxAI/streamlit-AddaxAI/frontend/analyse_advanced.py", line 162, in <module>
    add_deployment(selected_datetime)
  File "/Applications/AddaxAI_files/AddaxAI/streamlit-AddaxAI/backend/utils.py", line 544, in add_deployment
    "path": selected_folder,
            ^^^^^^^^^^^^^^^
NameError: name 'selected_folder' is not defined
2025-06-30 11:38:20.187 Uncaught app execution
Traceback (most recent call last):
  File "/Users/peter/miniforge3/envs/env-streamlit-addaxai/lib/python3.11/site-packages/streamlit/runtime/scriptrunner/exec_code.py", line 121, in exec_func_with_error_handling
    result = func()
             ^^^^^^
  File "/Users/peter/miniforge3/envs/env-streamlit-addaxai/lib/python3.11/site-packages/streamlit/runtime/scriptrunner/script_runner.py", line 645, in code_to_exec
    exec(code, module.__dict__)
  File "/Applications/AddaxAI_files/AddaxAI/streamlit-AddaxAI/frontend/main.py", line 250, in <module>
    pg.run()
  File "/Users/peter/miniforge3/envs/env-streamlit-addaxai/lib/python3.11/site-packages/streamlit/navigation/page.py", line 297, in run
    exec(code, module.__dict__)
  File "/Applications/AddaxAI_files/AddaxAI/streamlit-AddaxAI/frontend/analyse_advanced.py", line 103, in <module>
    projectID = project_selector_widget()
                ^^^^^^^^^^^^^^^^^^^^^^^^^
  File "/Applications/AddaxAI_files/AddaxAI/streamlit-AddaxAI/backend/utils.py", line 90, in project_selector_widget
    if settings["vars"]["analyse_advanced"]["selected_projectID"] != selected_projectID:
       ~~~~~~~~~~~~~~~~~~~~~~~~~~~~~~~~~~~~^^^^^^^^^^^^^^^^^^^^^^
KeyError: 'selected_projectID'
